Workbook

Sheet README
A1: Reverse TCO Tool v1 — Cloud AIaaS Spend to On-Prem NVIDIA Infrastructure
A3: PURPOSE: Start from a customer's current cloud AI spend and output (a) the on-prem NVIDIA fleet required to absorb the workload and (b) cost of ownership vs. continuing to rent, over 1/3/5 years.
A5: HOW TO USE:
A6: 1. Go to the Inputs tab. Yellow cells are for you to edit. Tier 1 needs only monthly spend + provider; every other yellow cell has a working default.
A7: 2. Results tab shows the comparison: floor case (no performance factors) first, then the adjusted case.
A8: 3. RateCard, Hardware, and PerfFactors tabs hold every price and assumption (blue text = editable data). Update them as prices change; nothing is hardcoded in formulas.
A9: 4. Validation tab reproduces NVIDIA's DGX TCO tool Test 1 from the same rate card. All checks must read PASS before customer use.
A11: COLOR LEGEND:
A12: Blue text = editable data value (rate card, registry, factors)
A13: Yellow fill = customer/analysis input cell (Inputs tab)
A14: Green text = formula linking to another tab
A15: Black text = same-tab formula
... A42: V2.7 (audit round 9 — final input-hardening pass): master guard extended with ISNUMBER + range checks for power rate (≥0), all three performance factors at their documented NVIDIA ranges (1-2.5 / 1-10 / 1-5 — guard and documentation now agree), Tier-3 GPU-hours (≥0), and lease factor/term (positive when populated); ALL remaining visible Results key-figure rows (systems, capex, headroom, exhaustion, displaced storage, lease view, one-time, residual, earliest-exhaustion, reconciliation, static payback) master-guarded so an invalid pasted input produces zero raw Excel errors anywhere on Results. Note: Excel compares text greater than numbers, so every guarded numeric field carries an explicit ISNUMBER check.

Sheet RateCard
A1: Rate Card — all editable (blue). Effective date + source in column C. | B1: Value | C1: Source / note
A3: CLOUD (AWS, B200-class 8-GPU instance; NVIDIA TCO tool defaults Jul 2026)
A4: Instance rate, on-demand ($/instance-hr) — B200 REFERENCE ROW; Engine uses CloudRates lookup since v2.3 | B4: 113.93 | C4: p6-b200.48xlarge class; NVIDIA TCO tool
A5: Instance rate, 1-yr reserved ($/instance-hr) — B200 REFERENCE ROW; Engine uses CloudRates lookup since v2.3 | B5: 68.36 | C5: NVIDIA TCO tool
A6: NVAIE support, on-demand ($/instance-hr) | B6: 8 | C6: NVIDIA TCO tool
A7: NVAIE support, 1-yr reserved ($/instance-hr) | B7: 2.88 | C7: NVIDIA TCO tool
A8: Fast storage ($/GB/mo) | B8: 0.14 | C8: Parallel FS class
A9: Bulk storage ($/GB/mo) | B9: 0.02 | C9: Object class
A10: Egress ($/GB) | B10: 0.05
A11: Egress volume (% of stored per month) | B11: 0.05 | C11: NVIDIA default 5%
A12: Cloud admin FTE, fully loaded ($/yr) | B12: 189000
A13: Billing/mgmt software ($/yr) | B13: 5000
A14: Cloud admin overhead (FTE) | B14: 0.01 | C14: Implied by NVIDIA Test 1 ($574/mo total admin)
A15: PaaS uplift (% over raw instance price) | B15: 0 | C15: 0 default; SageMaker/Vertex-style platforms typically 15-30%
A16: GPUs per cloud instance — LEGACY reference; Engine reads CloudRates!E per class since v2.5 | B16: 8
A18: ON-PREM (DGX B200 reference; NVIDIA TCO tool defaults Jul 2026)
A19: Cluster management server nodes ($/cluster, fixed) | B19: 600000 | C19: Charged once per cluster
A20: Professional services & installation ($/system) | B20: 25000
A21: Rack + PDUs ($/rack, compute) | B21: 15000 | C21: Storage rack cost is inside storage $/PB
A22: Fast storage hardware+software ($/PB) | B22: 1200000 | C22: Incl. chassis, rack, cables
A23: Fast storage support ($/PB/yr) | B23: 100000
A24: Bulk storage hardware+software ($/PB) | B24: 500000 | C24: Incl. chassis, rack, cables
A25: Bulk storage support ($/PB/yr) | B25: 33333
A26: Storage power (kW per PB) | B26: 10
A27: Storage racks per PB | B27: 1 | C27: Used for per-rack setup cost only
A28: Power cost ($/kW-month, fully loaded) | B28: 300 | C28: NVIDIA conservative default (~$0.41/kWh); override on Inputs
A29: Networking / VPN / firewall ($/mo) | B29: 3000
A30: Initial setup ($/rack, one-time; amortized over 36 mo) | B30: 2000
A31: Admin ratio (systems per FTE) | B31: 10
A32: On-prem admin FTE, fully loaded ($/yr) | B32: 189000
A33: Equinix Private AI bundle ($/system/mo) | B33: 11387 | C33: Colo + air/liquid cooling + interconnect + managed services; replaces power, facility, and admin lines
A35: OPERATING BASIS
A36: Hours per month | B36: 730 | C36: 24 x 365 / 12
A37: Ops/admin cost growth (%/yr, both sides) | B37: 0.04 | C37: NVIDIA default
A38: Rack setup amortization (months) | B38: 36

Sheet CloudRates
A1: Cloud instance rates by GPU class — AWS (workbook scope)
A2: GPU class | B2: Instance | C2: OD $/instance-hr | D2: 1-yr $/instance-hr | E2: GPUs | F2: OD confidence | G2: 1-yr confidence | H2: As of
A3: A100 | B3: p4d.24xlarge | C3: 32.8 | D3: 19.68 | E3: 8 | F3: LISTED — secondary tracker | G3: EST — 40% off OD assumption | H3: Jul-Aug 2026
A4: H100 | B4: p5.48xlarge | C4: 55.04 | D4: 33.02 | E4: 8 | F4: LISTED — secondary tracker | G4: EST — 40% off OD assumption | H4: Jul-Aug 2026
A5: H200 | B5: p5e.48xlarge | C5: 80 | D5: 48 | E5: 8 | F5: LISTED — secondary tracker | G5: EST — 40% off OD assumption | H5: Jul-Aug 2026
A6: B200 | B6: p6-b200.48xlarge | C6: 113.93 | D6: 68.36 | E6: 8 | F6: SNAPSHOT — NVIDIA TCO tool | G6: SNAPSHOT — NVIDIA TCO tool | H6: Jul 2026
A8: v2.4: each price carries its own provenance — AWS sells On-Demand, Savings Plans and Capacity Blocks as distinct purchasing constructs, so an assumed 40%-off rate is labeled EST, never implied as an AWS-listed reserved price. B200 row = NVIDIA TCO tool snapshot (both prices). NVAIE support stays on RateCard (B6/B7, per instance-hr). B300 is intentionally absent: workbook blocks it pending a benchmark-derived factor; the web calculator offers it with EST-flagged rates and a provisional capability index.

Sheet Hardware
A1: On-Prem System Registry — add rows as new systems are priced (blue = editable)
A2: System | B2: GPUs | C2: System cost | D2: SW suite | E2: Compute fabric | F2: Storage fabric | G2: Mgmt fabric | H2: kW per system (avg) | I2: Sys/rack | J2: Priced? | K2: Note
A3: DGX B200 | B3: 8 | C3: 485000 | D3: 142800 | E3: 54323 | F3: 23443 | G3: 14227 | H3: 14.4 | I3: 2 | J3: YES | K3: NVIDIA TCO tool Jul 2026
A4: DGX B300 | B4: 8 | C4: 0 | D4: 0 | E4: 0 | F4: 0 | G4: 0 | H4: 14.4 | I4: 2 | J4: NO | K4: Placeholder — price before selecting
A5: DGX H200 | B5: 8 | C5: 0 | D5: 0 | E5: 0 | F5: 0 | G5: 0 | H5: 10.2 | I5: 2 | J5: NO | K5: Placeholder — price before selecting
A6: DGX GB200 NVL-72 | B6: 72 | C6: 0 | D6: 0 | E6: 0 | F6: 0 | G6: 0 | H6: 120 | I6: 1 | J6: NO | K6: Placeholder — price before selecting
A8: Cloud GPU class list (drives PerfFactors lookups; keep in sync with PerfFactors rows):
A9: A100
A10: H100
A11: H200
A12: B200

Sheet PerfFactors
A1: Generational performance factors: cloud GPU class -> DGX B200 target (blue = editable)
A2: Cloud GPU class | B2: Training (default) | C2: Training (max) | D2: Inference (default) | E2: Inference (max) | F2: Source / note
A3: A100 | B3: 4.4 | C3: 8 | D3: 12 | E3: 18 | F3: Chained: A100->H100 (2.0x train / 3.0x infer, conservative from MLPerf 4.5x max) x H100->B200
A4: H100 | B4: 2.2 | C4: 3 | D4: 4 | E4: 15 | F4: MLPerf v4.1: 2.0-2.2x training. Inference 4x MLPerf; 15x = NVIDIA best-case FP4
A5: H200 | B5: 1.5 | C5: 2 | D5: 2.9 | E5: 10 | F5: Derived: H100 factors / H200-vs-H100 (1.4-1.47x train, ~1.4x infer)
A6: B200 | B6: 1 | C6: 1 | D6: 1 | E6: 1 | F6: Like-for-like silicon
A8: Rule: defaults = MLPerf-audited/derived (conservative); max = NVIDIA marketing upper bound. Floor case in Results ignores this table entirely (all factors = 1.0).
A9: Additional multiplicative factors (network / AI Factory software / NVAIE) are set on the Inputs tab with NVIDIA's range-default-breakeven guidance.

Sheet Inputs
A1: Customer & Analysis Inputs — edit YELLOW cells only | B1: Value | C1: Guidance
A3: TIER 1 — required (hallway conversation)
A4: Monthly cloud AI spend ($) | B4: 105079 | C4: Approximates NVIDIA Test 1 (~1% high; exact compute share would be 49.491%)
A5: Primary provider | B5: AWS | C5: AWS ONLY in this workbook — any other selection deliberately stops the calculation (NA errors). Use the web calculator for Azure / GCP / OCI / CoreWeave.
A7: TIER 2 — refine when known (defaults otherwise)
A8: Current cloud GPU class | B8: H100 | C8: A100 / H100 / H200 / B200 only. B300 renters: use the web calculator — the workbook blocks B300 pending a benchmark-derived B300→B200 factor (audit round 6).
A9: Workload mix: training share (%) | B9: 0.5 | C9: Inference share = 1 - this. Gates the generational factor.
A10: Commitment mix: on-demand share (%) | B10: 0 | C10: Remainder priced at 1-yr reserved rates
A11: Total storage (PB) | B11: 1 | C11: Used only when Storage mode = Known (Inputs!B38); Auto derives PB from the bill
A12: Fast storage share (%) | B12: 0.25 | C12: Remainder is bulk
A13: Compute share of monthly bill (%) | B13: 0.5 | C13: Tier-1 decomposition default (NVIDIA Test 1 derived); storage+admin = remainder
A14: Annual compute growth (%) | B14: 0.25 | C14: Almost no AI consumption is flat; 0% = NVIDIA's assumption
A15: Facility | B15: Self-hosted | C15: Self-hosted or Equinix
A16: Power rate override ($/kW-month) | B16: 300 | C16: Self-hosted only. NVIDIA default 300; SLED muni power often 150-200
A17: Target on-prem utilization (%) | B17: 0.85 | C17: De-rated from NVIDIA's implicit 100% for realism
A18: On-prem system (from Hardware registry) | B18: DGX B200 | C18: Only priced systems (Hardware col J = YES)
A20: TIER 3 — validated analysis (overrides)
A21: Actual monthly GPU-hours (from invoice; 0 = not provided) | B21: 0 | C21: If > 0, overrides the spend-based reconstruction
A23: PERFORMANCE FACTORS (beyond generational; NVIDIA range / default / breakeven)
A24: Network (RA InfiniBand) factor | B24: 1 | C24: Range 1-2.5x; NVIDIA default 1.5x; breakeven 1.05x. Keep 1.0 for single-node/inference-only shops
A25: AI Factory software (Run:ai/BCM) factor | B25: 1.3 | C25: Range 1-10x; default 1.3x (util 70->90%); breakeven 1.1x
A26: NVAIE / NIMs factor | B26: 1.3 | C26: Range 1-5x; default 1.3x; breakeven 1.1x
A28: FINANCING (optional — leave factor blank for capex-only view)
A29: Lease rate factor (monthly, day-of quote) | C29: e.g., NVIDIA illustrative 3-yr factor was 0.0281. Blank = no lease view
A30: Lease term (months) | B30: 36 | C30: Informational only — not used in any workbook calculation (web/deploy-phase financing field)
A32: V1.2 — TRANSITION, FACILITY, RESILIENCE, RESIDUAL
A33: Facility retrofit, one-time ($; self-hosted retrofit only, else 0) | B33: 0 | C33: ~$10-15K per kW of new capacity; 2 DGX/rack = ~29 kW/rack
A34: Migration engineering, one-time ($) | B34: 100000 | C34: MLOps re-platforming; scale with workload complexity
A35: Dual-run period (months) | B35: 2 | C35: Customer pays cloud AND on-prem during migration
A36: N+1 redundancy (1 = yes, 0 = no) | B36: 0 | C36: Adds one system to both fleets; material at small scale
A37: Residual value (% of systems + storage capex at horizon) | B37: 0.15 | C37: Flat % simplification; excludes cluster nodes/racks/one-time
A38: Storage mode (Auto = derive PB from bill; Known = use entered PB) | B38: Auto | C38: v2.3: Tier 1 is a true two-input model — Auto sizes storage from the non-compute share of the bill; enter Known + PB for Tier 2/3 precision

Sheet Engine
A1: Calculation Engine — no edits here (green = cross-tab links) | B1: Value | C1: Logic
A3: STEP 1 — Normalize spend to cloud GPU-hours
A4: Blended cloud rate ($/instance-hr) | B4: =IF(Inputs!$B$5<>"AWS",NA(),(Inputs!$B$10*(INDEX(CloudRates!$C$3:$C$6,MATCH(Inputs!$B$8,CloudRates!$A$3:$A$6,0))+RateCard!$B$6)+(1-Inputs!$B$10)*(INDEX(CloudRates!$D$3:$D$6,MATCH(Inputs!$B$8,CloudRates!$A$3:$A$6,0))+RateCard!$B$7))*(1+RateCard!$B$15)) -> 35.9 | C4: v2.4: hard-stops (NA) for non-AWS providers — prevents screenshotting AWS math under another provider's name; v2.3 class routing retained
A5: Estimated monthly compute spend ($) | B5: =Inputs!$B$4*Inputs!$B$13 -> 52539.5 | C5: Bill x compute share
A6: Instance-hours per month | B6: =B5/B4 -> 1463.4958
A7: Cloud GPU-hours per month | B7: =IF(Inputs!$B$21>0,Inputs!$B$21,B6*INDEX(CloudRates!$E$3:$E$6,MATCH(Inputs!$B$8,CloudRates!$A$3:$A$6,0))) -> 11707.967 | C7: v2.5: GPU count read from the CloudRates registry row (was legacy RateCard!B16 constant)
A9: STEP 2 — Net Performance Factor
A10: Generational factor (workload-weighted) | B10: =1/(Inputs!$B$9/INDEX(PerfFactors!$B$3:$B$6,MATCH(Inputs!$B$8,PerfFactors!$A$3:$A$6,0))+(1-Inputs!$B$9)/INDEX(PerfFactors!$D$3:$D$6,MATCH(Inputs!$B$8,PerfFactors!$A$3:$A$6,0))) -> 2.8387097 | C10: v2.0: harmonic blend — workload shares are GPU-hour shares (audit P0-2)
A11: Net Performance Factor (NPF) | B11: =B10*Inputs!$B$24*Inputs!$B$25*Inputs!$B$26 -> 4.7974194 | C11: x network x AI Factory SW x NVAIE
A12: Effective on-prem GPU-hours needed | B12: =B7/B11 -> 2440.4718
A13: Floor-case GPU-hours (NPF = 1.0) | B13: =B7 -> 11707.967 | C13: Credibility anchor
A15: STEP 3 — Fleet sizing
A16: GPUs per on-prem system | B16: =INDEX(Hardware!$B$3:$B$6,MATCH(Inputs!$B$18,Hardware!$A$3:$A$6,0)) -> 8
A17: GPU-hours per system per month | B17: =B16*RateCard!$B$36*Inputs!$B$17 -> 4964 | C17: GPUs x 730 x target utilization
A18: Systems required (adjusted case) | B18: =CEILING(B12/B17,1)+Inputs!$B$36 -> 1
A19: Systems required (floor case) | B19: =CEILING(B13/B17,1)+Inputs!$B$36 -> 3
A20: Growth headroom (adjusted case) | B20: =1-B12/((B18-Inputs!$B$36)*B17) -> 0.50836588 | C20: v2.2: headroom uses PRODUCTIVE systems (total − N+1 spare); spare capacity is not growth capacity
A22: STEP 4 — Storage
A23: Fast storage (PB) | B23: =B62*Inputs!$B$12 -> 0.24745397
A24: Bulk storage (PB) | B24: =B62*(1-Inputs!$B$12) -> 0.7423619
A25: Cloud storage + egress cost ($/mo, reconstructed) | B25: =B23*1000000*RateCard!$B$8+B24*1000000*RateCard!$B$9+B62*1000000*RateCard!$B$11*RateCard!$B$10 -> 51965.333 | C25: Disappears on-prem (egress ~ $0)
A26: Cloud admin ($/mo, reconstructed) | B26: =RateCard!$B$13/12+RateCard!$B$14*RateCard!$B$12/12 -> 574.16667
A28: STEP 5 — On-prem cost stack (ADJUSTED case)
A29: Per-system acquisition ($) | B29: =IF(OR(INDEX(Hardware!$J$3:$J$6,MATCH(Inputs!$B$18,Hardware!$A$3:$A$6,0))<>"YES",INDEX(Hardware!$B$3:$B$6,MATCH(Inputs!$B$18,Hardware!$A$3:$A$6,0))=0),NA(),INDEX(Hardware!$C$3:$C$6,MATCH(Inputs!$B$18,Hardware!$A$3:$A$6,0))+INDEX(Hardware!$D$3:$D$6,MATCH(Inputs!$B$18,Hardware!$A$3:$A$6,0))+INDEX(Hardware!$E$3:$E$6,MATCH(Inputs!$B$18,Hardware!$A$3:$A$6,0))+INDEX(Hardware!$F$3:$F$6,MATCH(Inputs!$B$18,Hardware!$A$3:$A$6,0))+INDEX(Hardware!$G$3:$G$6,MATCH(Inputs!$B$18,Hardware!$A$3:$A$6,0))+RateCard!$B$20) -> 744793 | C29: v2.2 guard: requires Hardware Priced?=YES and GPU count > 0; otherwise deliberate NA error
A30: Compute racks | B30: =CEILING(B18/INDEX(Hardware!$I$3:$I$6,MATCH(Inputs!$B$18,Hardware!$A$3:$A$6,0)),1) -> 1
A31: Capex: compute + network ($) | B31: =B18*B29+RateCard!$B$19+B30*RateCard!$B$21 -> 1359793 | C31: Incl. $ fixed cluster mgmt nodes
A32: Capex: storage ($) | B32: =B23*RateCard!$B$22+B24*RateCard!$B$24 -> 668125.71
A33: TOTAL CAPEX ($) | B33: =B31+B32 -> 2027918.7
A34: System kW | B34: =INDEX(Hardware!$H$3:$H$6,MATCH(Inputs!$B$18,Hardware!$A$3:$A$6,0)) -> 14.4
A35: Opex: power ($/mo) | B35: =(B18*B34+B62*RateCard!$B$26)*Inputs!$B$16 -> 7289.4476 | C35: Self-hosted branch
A36: Total racks (compute + storage) | B36: =B30+B62*RateCard!$B$27 -> 1.9898159
A37: Opex: other facility ($/mo) | B37: =RateCard!$B$29+RateCard!$B$30*B36/RateCard!$B$38 -> 3110.5453 | C37: Network/VPN/firewall + amortized setup
A38: Opex: admin ($/mo) | B38: =B18/RateCard!$B$31*RateCard!$B$32/12 -> 1575 | C38: Self-hosted branch
A39: Opex: storage support ($/mo) | B39: =(B23*RateCard!$B$23+B24*RateCard!$B$25)/12 -> 4124.2122 | C39: Both branches
A40: Opex: self-hosted total ($/mo) | B40: =B35+B37+B38+B39 -> 16099.205
A41: Opex: Equinix total ($/mo) | B41: =B18*RateCard!$B$33+B39 -> 15511.212 | C41: Bundle incl. power, facility, managed svcs (admin = 0)
A42: SELECTED OPEX ($/mo) | B42: =IF(Inputs!$B$15="Equinix",B41,B40) -> 16099.205
A44: STEP 5b — On-prem cost stack (FLOOR case: NPF = 1.0)
A45: Capex ($) | B45: =B19*B29+RateCard!$B$19+CEILING(B19/INDEX(Hardware!$I$3:$I$6,MATCH(Inputs!$B$18,Hardware!$A$3:$A$6,0)),1)*RateCard!$B$21+B32 -> 3532504.7
A46: Opex: self-hosted ($/mo) | B46: =(B19*B34+B62*RateCard!$B$26)*Inputs!$B$16+RateCard!$B$29+RateCard!$B$30*(CEILING(B19/INDEX(Hardware!$I$3:$I$6,MATCH(Inputs!$B$18,Hardware!$A$3:$A$6,0)),1)+B62*RateCard!$B$27)/RateCard!$B$38+B19/RateCard!$B$31*RateCard!$B$32/12+B39 -> 27944.761
...

Sheet Results
A1: Results — Cloud vs. On-Prem
A2: All figures from Engine + Inputs. Cloud compute grows at the compute growth rate; cloud storage/admin and all on-prem opex grow at the ops growth rate.
A4: ANNUAL TRAJECTORY
B5: Year 1 | C5: Year 2 | D5: Year 3 | E5: Year 4 | F5: Year 5
A6: Cloud cost ($/yr) | B6: =IF(Engine!$B$63=FALSE(),"N/A — see input guard",12*(Inputs!$B$4*Inputs!$B$13*(1+Inputs!$B$14)^0+Inputs!$B$4*(1-Inputs!$B$13)*(1+RateCard!$B$37)^0)) -> 1260948 | C6: =IF(Engine!$B$63=FALSE(),"N/A — see input guard",12*(Inputs!$B$4*Inputs!$B$13*(1+Inputs!$B$14)^1+Inputs!$B$4*(1-Inputs!$B$13)*(1+RateCard!$B$37)^1)) -> 1443785.5 | D6: =IF(Engine!$B$63=FALSE(),"N/A — see input guard",12*(Inputs!$B$4*Inputs!$B$13*(1+Inputs!$B$14)^2+Inputs!$B$4*(1-Inputs!$B$13)*(1+RateCard!$B$37)^2)) -> 1667036.3 | E6: =IF(Engine!$B$63=FALSE(),"N/A — see input guard",12*(Inputs!$B$4*Inputs!$B$13*(1+Inputs!$B$14)^3+Inputs!$B$4*(1-Inputs!$B$13)*(1+RateCard!$B$37)^3)) -> 1940592 | F6: =IF(Engine!$B$63=FALSE(),"N/A — see input guard",12*(Inputs!$B$4*Inputs!$B$13*(1+Inputs!$B$14)^4+Inputs!$B$4*(1-Inputs!$B$13)*(1+RateCard!$B$37)^4)) -> 2276808.6
A7: On-prem opex, adjusted case ($/yr) | B7: =IF(Engine!$B$63=FALSE(),"N/A — see input guard",12*Engine!$B$42*(1+RateCard!$B$37)^0) -> 193190.46 | C7: =IF(Engine!$B$63=FALSE(),"N/A — see input guard",12*Engine!$B$42*(1+RateCard!$B$37)^1) -> 200918.08 | D7: =IF(Engine!$B$63=FALSE(),"N/A — see input guard",12*Engine!$B$42*(1+RateCard!$B$37)^2) -> 208954.8 | E7: =IF(Engine!$B$63=FALSE(),"N/A — see input guard",12*Engine!$B$42*(1+RateCard!$B$37)^3) -> 217313 | F7: =IF(Engine!$B$63=FALSE(),"N/A — see input guard",12*Engine!$B$42*(1+RateCard!$B$37)^4) -> 226005.52
A8: On-prem opex, floor case ($/yr) | B8: =IF(Engine!$B$63=FALSE(),"N/A — see input guard",12*Engine!$B$48*(1+RateCard!$B$37)^0) -> 335337.13 | C8: =IF(Engine!$B$63=FALSE(),"N/A — see input guard",12*Engine!$B$48*(1+RateCard!$B$37)^1) -> 348750.61 | D8: =IF(Engine!$B$63=FALSE(),"N/A — see input guard",12*Engine!$B$48*(1+RateCard!$B$37)^2) -> 362700.64 | E8: =IF(Engine!$B$63=FALSE(),"N/A — see input guard",12*Engine!$B$48*(1+RateCard!$B$37)^3) -> 377208.66 | F8: =IF(Engine!$B$63=FALSE(),"N/A — see input guard",12*Engine!$B$48*(1+RateCard!$B$37)^4) -> 392297.01
A10: TOTALS (capex view)
B11: 1 Year | C11: 3 Years | D11: 5 Years
A12: Cloud total ($) | B12: =SUM($B$6:B6) -> 1260948 | C12: =SUM($B$6:D6) -> 4371769.8 | D12: =SUM($B$6:F6) -> 8589170.4
A13: On-prem total, FLOOR — credibility anchor, no performance credit (capex + one-time - residual + opex) ($) | B13: =IF(Engine!$B$63=FALSE(),"N/A — see input guard",IF(Engine!$B$65<1,"N/A — capacity exhausted yr "&TEXT(Engine!$B$65,"0.0")&"; use web model",Engine!$B$45+Engine!$B$54-Engine!$B$56+SUM($B$8:B8))) -> 3867624.9 | C13: =IF(Engine!$B$63=FALSE(),"N/A — see input guard",IF(Engine!$B$65<3,"N/A — capacity exhausted yr "&TEXT(Engine!$B$65,"0.0")&"; use web model",Engine!$B$45+Engine!$B$54-Engine!$B$56+SUM($B$8:D8))) -> N/A — capacity exhausted yr 1.1; use web model | D13: =IF(Engine!$B$63=FALSE(),"N/A — see input guard",IF(Engine!$B$65<5,"N/A — capacity exhausted yr "&TEXT(Engine!$B$65,"0.0")&"; use web model",Engine!$B$45+Engine!$B$54-Engine!$B$56+SUM($B$8:F8))) -> N/A — capacity exhausted yr 1.1; use web model
A14: SAVINGS, floor case ($) | B14: =IF(ISNUMBER(B13),B12-B13,"N/A — see on-prem total") -> -2606676.9 | C14: =IF(ISNUMBER(C13),C12-C13,"N/A — see on-prem total") -> N/A — see on-prem total | D14: =IF(ISNUMBER(D13),D12-D13,"N/A — see on-prem total") -> N/A — see on-prem total
A15: Savings, floor case (%) | B15: =IF(ISNUMBER(B14),B14/B12,"—") -> -2.0672359 | C15: =IF(ISNUMBER(C14),C14/C12,"—") -> — | D15: =IF(ISNUMBER(D14),D14/D12,"—") -> —
A16: On-prem total, ADJUSTED (capex + one-time - residual + opex) ($) | B16: =IF(Engine!$B$63=FALSE(),"N/A — see input guard",IF(Engine!$B$64<1,"N/A — capacity exhausted yr "&TEXT(Engine!$B$64,"0.0")&"; use web model",Engine!$B$33+Engine!$B$54-Engine!$B$55+SUM($B$7:B7))) -> 2393990.2 | C16: =IF(Engine!$B$63=FALSE(),"N/A — see input guard",IF(Engine!$B$64<3,"N/A — capacity exhausted yr "&TEXT(Engine!$B$64,"0.0")&"; use web model",Engine!$B$33+Engine!$B$54-Engine!$B$55+SUM($B$7:D7))) -> 2803863 | D16: =IF(Engine!$B$63=FALSE(),"N/A — see input guard",IF(Engine!$B$64<5,"N/A — capacity exhausted yr "&TEXT(Engine!$B$64,"0.0")&"; use web model",Engine!$B$33+Engine!$B$54-Engine!$B$55+SUM($B$7:F7))) -> N/A — capacity exhausted yr 3.2; use web model
A17: SAVINGS, adjusted ($) | B17: =IF(ISNUMBER(B16),B12-B16,"N/A — see on-prem total") -> -1133042.2 | C17: =IF(ISNUMBER(C16),C12-C16,"N/A — see on-prem total") -> 1567906.7 | D17: =IF(ISNUMBER(D16),D12-D16,"N/A — see on-prem total") -> N/A — see on-prem total
A18: Savings, adjusted (%) | B18: =IF(ISNUMBER(B17),B17/B12,"—") -> -0.89856375 | C18: =IF(ISNUMBER(C17),C17/C12,"—") -> 0.35864348 | D18: =IF(ISNUMBER(D17),D17/D12,"—") -> —
A20: KEY FIGURES
A21: Systems required (adjusted / floor) | B21: =IF(Engine!$B$63=FALSE(),"N/A — see input guard",Engine!$B$18&" / "&Engine!$B$19) -> 1 / 3
A22: Total capex, adjusted ($) | B22: =IF(Engine!$B$63=FALSE(),"N/A — see input guard",Engine!$B$33) -> 2027918.7
A23: Growth headroom in year-1 fleet (adjusted / floor) | B23: =IF(Engine!$B$63=FALSE(),"N/A — see input guard",TEXT(Engine!$B$20,"0.0%")&" / "&TEXT(1-Engine!$B$13/((Engine!$B$19-Inputs!$B$36)*Engine!$B$17),"0.0%")) -> 50.8% / 21.4%
A24: Years until growth exhausts headroom (adjusted / floor) | B24: =IF(Engine!$B$63=FALSE(),"N/A — see input guard",IF(Inputs!$B$14=0,"n/a (no growth)",TEXT(LN(1/(1-Engine!$B$20))/LN(1+Inputs!$B$14),"0.0")&" / "&TEXT(LN(1/(1-(1-Engine!$B$13/((Engine!$B$19-Inputs!$B$36)*Engine!$B$17))))/LN(1+Inputs!$B$14),"0.0"))) -> 3.2 / 1.1
A25: Cloud storage + egress spend displaced by on-prem storage modeled above ($/mo) | B25: =IF(Engine!$B$63=FALSE(),"N/A — see input guard",Engine!$B$25) -> 51965.333
A26: Crossover month (cumulative monthly cash flows, adjusted case) | B26: =IF(Engine!$B$63=FALSE(),"see input guards — invalid input state for this workbook",IF(ISNA(MATCH(1,Crossover!$D$2:$D$61,0)),"no crossover within 60 months under the modeled trajectory",IF(Inputs!$B$14=0,"Month "&MATCH(1,Crossover!$D$2:$D$61,0),IF(MATCH(1,Crossover!$D$2:$D$61,0)>12*LN(1/(1-Engine!$B$20))/LN(1+Inputs!$B$14),"crossover cannot be determined in the workbook — additional capacity is required before breakeven; use the dynamic web model","Month "&MATCH(1,Crossover!$D$2:$D$61,0))))) -> Month 25
A27: Lease view, adjusted ($/mo, if factor entered) | B27: =IF(Engine!$B$63=FALSE(),"N/A — see input guard",Engine!$B$51) -> not entered
A28: One-time transition & exit costs ($) | B28: =IF(Engine!$B$63=FALSE(),"N/A — see input guard",Engine!$B$54) -> 359648.79
A29: Residual credit at horizon, adjusted ($) | B29: =IF(Engine!$B$63=FALSE(),"N/A — see input guard",Engine!$B$55) -> 186767.81
A30: ⚠ WORKBOOK LIMITATION: fleet expansion under growth is NOT modeled here (web engine v2.x models it). Earliest exhaustion, either case (years): | B30: =IF(Engine!$B$63=FALSE(),"N/A — see input guard",IF(Inputs!$B$14=0,"n/a (no growth)",MIN(LN(1/(1-Engine!$B$20))/LN(1+Inputs!$B$14),LN(1/(1-(1-Engine!$B$13/((Engine!$B$19-Inputs!$B$36)*Engine!$B$17))))/LN(1+Inputs!$B$14)))) -> 1.0780264
A31: Totals for horizons beyond the EARLIER of the two exhaustion years understate on-prem cost (the floor case usually exhausts first — audit round 3). Treat longer-horizon results as directional only.
A32: Spend/storage reconciliation | B32: =IF(Engine!$B$63=FALSE(),"N/A — see input guard",Engine!$B$60) -> OK — within 2% tolerance (difference $0/mo)
A33: Simple static payback, adjusted (months — SECONDARY metric only) | B33: =IF(Engine!$B$63=FALSE(),"N/A — see input guard",IF(Inputs!$B$4-Engine!$B$42<=0,"n/a (opex exceeds bill)",(Engine!$B$33+Engine!$B$54)/(Inputs!$B$4-Engine!$B$42))) -> 26.832693
A34: Provider guard | B34: =IF(Inputs!$B$5<>"AWS","⚠ Workbook reference implementation supports AWS only — use the web calculator for this provider","AWS — OK") -> AWS — OK
A35: GPU class guard | B35: =IF(ISNA(MATCH(Inputs!$B$8,CloudRates!$A$3:$A$6,0)),"⚠ Unsupported GPU class in reference workbook — use A100/H100/H200/B200 or the web calculator","OK") -> OK
A36: Master input guard | B36: =IF(Engine!$B$63,"OK — all inputs valid","⚠ Invalid input state (out-of-range or pasted value) — economics suppressed; see guards above") -> OK — all inputs valid

Sheet Validation
A1: Validation — reproduce NVIDIA DGX TCO tool Test 1 from this rate card
A2: Scenario: 1x DGX B200 vs AWS B200-class, all perf factors 1.00, 100% utilization, 100% 1-yr reserved, 0.25 PB fast + 0.75 PB bulk, self-hosted. Expected values from NVIDIA tool screenshots (Aug 2026). Tolerance MAX($1, 0.01%) — tightened in v2.3 to match the live regression standard.
A4: Check | B4: This workbook | C4: NVIDIA tool | D4: Status
A5: Monthly GPU-hours per DGX (100% util) | B5: =8*RateCard!$B$36 -> 5840 | C5: 5840 | D5: =IF(ABS(B5-C5)<=MAX(1,0.0001*ABS(C5)),"PASS","FAIL") -> PASS
A6: Cloud compute ($/mo) | B6: =730*(RateCard!$B$5+RateCard!$B$7) -> 52005.2 | C6: 52005 | D6: =IF(ABS(B6-C6)<=MAX(1,0.0001*ABS(C6)),"PASS","FAIL") -> PASS
A7: Cloud storage + egress ($/mo) | B7: =0.25*1000000*RateCard!$B$8+0.75*1000000*RateCard!$B$9+1*1000000*RateCard!$B$11*RateCard!$B$10 -> 52500 | C7: 52500 | D7: =IF(ABS(B7-C7)<=MAX(1,0.0001*ABS(C7)),"PASS","FAIL") -> PASS
A8: Cloud admin ($/mo) | B8: =RateCard!$B$13/12+RateCard!$B$14*RateCard!$B$12/12 -> 574.16667 | C8: 574 | D8: =IF(ABS(B8-C8)<=MAX(1,0.0001*ABS(C8)),"PASS","FAIL") -> PASS
A9: Cloud total ($/mo) | B9: =B6+B7+B8 -> 105079.37 | C9: 105079 | D9: =IF(ABS(B9-C9)<=MAX(1,0.0001*ABS(C9)),"PASS","FAIL") -> PASS
A10: On-prem compute+network capex ($) | B10: =1*(485000+142800+54323+23443+14227+RateCard!$B$20)+RateCard!$B$19+1*RateCard!$B$21 -> 1359793 | C10: 1359793 | D10: =IF(ABS(B10-C10)<=MAX(1,0.0001*ABS(C10)),"PASS","FAIL") -> PASS
A11: On-prem storage capex ($) | B11: =0.25*RateCard!$B$22+0.75*RateCard!$B$24 -> 675000 | C11: 675000 | D11: =IF(ABS(B11-C11)<=MAX(1,0.0001*ABS(C11)),"PASS","FAIL") -> PASS
A12: Storage support ($/mo) | B12: =(0.25*RateCard!$B$23+0.75*RateCard!$B$25)/12 -> 4166.6458 | C12: 4167 | D12: =IF(ABS(B12-C12)<=MAX(1,0.0001*ABS(C12)),"PASS","FAIL") -> PASS
A13: Ops: power ($/mo) | B13: =(1*14.4+1*RateCard!$B$26)*RateCard!$B$28 -> 7320 | C13: 7320 | D13: =IF(ABS(B13-C13)<=MAX(1,0.0001*ABS(C13)),"PASS","FAIL") -> PASS
A14: Ops: other facility ($/mo) | B14: =RateCard!$B$29+RateCard!$B$30*(1+0.75)/36 -> 3097.2222 | C14: 3097 | D14: =IF(ABS(B14-C14)<=MAX(1,0.0001*ABS(C14)),"PASS","FAIL") -> PASS
A15: Ops: admin ($/mo) | B15: =1/RateCard!$B$31*RateCard!$B$32/12 -> 1575 | C15: 1575 | D15: =IF(ABS(B15-C15)<=MAX(1,0.0001*ABS(C15)),"PASS","FAIL") -> PASS
A16: Ops total ($/mo) | B16: =B13+B14+B15 -> 11992.222 | C16: 11992 | D16: =IF(ABS(B16-C16)<=MAX(1,0.0001*ABS(C16)),"PASS","FAIL") -> PASS
A17: Equinix ops total ($/mo) | B17: =1*RateCard!$B$33 -> 11387 | C17: 11387 | D17: =IF(ABS(B17-C17)<=MAX(1,0.0001*ABS(C17)),"PASS","FAIL") -> PASS
A18: Lease check: compute ($/mo @ 0.0281) | B18: =B10*0.0281 -> 38210.183 | C18: 38210 | D18: =IF(ABS(B18-C18)<=MAX(1,0.0001*ABS(C18)),"PASS","FAIL") -> PASS
A19: Lease check: storage ($/mo @ 0.0281) | B19: =B11*0.0281+B12 -> 23134.146 | C19: 23135 | D19: =IF(ABS(B19-C19)<=MAX(1,0.0001*ABS(C19)),"PASS","FAIL") -> PASS
A20: On-prem monthly total, leased ($/mo) | B20: =B18+B19+B16 -> 73336.551 | C20: 73337 | D20: =IF(ABS(B20-C20)<=MAX(1,0.0001*ABS(C20)),"PASS","FAIL") -> PASS
A21: v2.3: tolerance tightened to MAX($1, 0.01%) matching the live regression standard (was 1%).
A22: All rows must read PASS before customer use. If a rate card value changes, expected values here describe the NVIDIA tool snapshot, not your new reality — they exist to prove the formula logic, not to freeze prices.

Sheet EngineRegression
A1: Engine Regression — NVIDIA Test 1 fixture (audit P0-3 response)
A2: Set the Inputs tab to the fixture below, then every check compares the LIVE Engine/Results cells (not shadow formulas) to expected values under the engine's documented conventions. Tolerance: MAX($1, 0.01%). Note: 'Other facility' expected is $3,111 (engine counts 1.0 storage rack for 1.0 PB) vs NVIDIA's $3,097 (0.75 racks) — a documented convention difference of $14/mo.
A4: FIXTURE (set these on Inputs):
A5: Inputs!B4 Monthly spend | B5: 105079
A6: Inputs!B13 Compute share | B6: 0.49491
A7: Inputs!B8 GPU class | B7: B200
A8: Inputs!B9 Training share | B8: 0.5
A9: Inputs!B10 OD share | B9: 0
A10: Inputs!B11 Storage PB | B10: 1
A11: Inputs!B12 Fast share | B11: 0.25
A12: Inputs!B14 Growth | B12: 0
A13: Inputs!B15 Facility | B13: Self-hosted
A14: Inputs!B16 Power | B14: 300
A15: Inputs!B17 Utilization | B15: 1
A16: Inputs!B18 System | B16: DGX B200
A17: Inputs!B21 Tier3 hrs | B17: 0
A18: Inputs!B24-26 Factors | B18: 1.0 / 1.0 / 1.0
A19: Inputs!B33-B37 Retrofit/Migr/Dual/N+1/Resid | B19: 0 / 0 / 0 / 0 / 0%
A20: Inputs!B38 Storage mode | B20: Known
A21: Fixture loaded? | B21: =IF(AND(Inputs!$B$4=105079,ABS(Inputs!$B$13-0.49491)<0.0001,Inputs!$B$9=0.5,Inputs!$B$10=0,Inputs!$B$11=1,Inputs!$B$12=0.25,Inputs!$B$14=0,Inputs!$B$16=300,Inputs!$B$17=1,Inputs!$B$24=1,Inputs!$B$25=1,Inputs!$B$26=1,Inputs!$B$21=0,Inputs!$B$34=0,Inputs!$B$35=0,Inputs!$B$36=0,Inputs!$B$37=0,Inputs!$B$33=0,Inputs!$B$8="B200",Inputs!$B$15="Self-hosted",Inputs!$B$18="DGX B200",Inputs!$B$5="AWS",Inputs!$B$38="Known"),"YES","NO — set fixture first") -> NO — set fixture first
A23: Check (live Engine/Results cell) | B23: Engine value | C23: Expected | D23: Status
A24: Cloud GPU-hours/mo (Engine!B7) | B24: =Engine!$B$7 -> 11707.967 | C24: 5840 | D24: =IF($B$21<>"YES","FIXTURE NOT LOADED",IF(ABS(B24-C24)<=MAX(1,0.0001*MAX(ABS(C24),1)),"PASS","FAIL")) -> FIXTURE NOT LOADED
A25: Blended rate $/instance-hr (Engine!B4) | B25: =Engine!$B$4 -> 35.9 | C25: 71.24 | D25: =IF($B$21<>"YES","FIXTURE NOT LOADED",IF(ABS(B25-C25)<=MAX(1,0.0001*MAX(ABS(C25),1)),"PASS","FAIL")) -> FIXTURE NOT LOADED
A26: Net Performance Factor (Engine!B11) | B26: =Engine!$B$11 -> 4.7974194 | C26: 1 | D26: =IF($B$21<>"YES","FIXTURE NOT LOADED",IF(ABS(B26-C26)<=MAX(1,0.0001*MAX(ABS(C26),1)),"PASS","FAIL")) -> FIXTURE NOT LOADED
A27: Systems required, adjusted (Engine!B18) | B27: =Engine!$B$18 -> 1 | C27: 1 | D27: =IF($B$21<>"YES","FIXTURE NOT LOADED",IF(ABS(B27-C27)<=MAX(1,0.0001*MAX(ABS(C27),1)),"PASS","FAIL")) -> FIXTURE NOT LOADED
A28: Systems required, floor (Engine!B19) | B28: =Engine!$B$19 -> 3 | C28: 1 | D28: =IF($B$21<>"YES","FIXTURE NOT LOADED",IF(ABS(B28-C28)<=MAX(1,0.0001*MAX(ABS(C28),1)),"PASS","FAIL")) -> FIXTURE NOT LOADED
A29: Capex compute+network (Engine!B31) | B29: =Engine!$B$31 -> 1359793 | C29: 1359793 | D29: =IF($B$21<>"YES","FIXTURE NOT LOADED",IF(ABS(B29-C29)<=MAX(1,0.0001*MAX(ABS(C29),1)),"PASS","FAIL")) -> FIXTURE NOT LOADED
A30: Capex storage (Engine!B32) | B30: =Engine!$B$32 -> 668125.71 | C30: 675000 | D30: =IF($B$21<>"YES","FIXTURE NOT LOADED",IF(ABS(B30-C30)<=MAX(1,0.0001*MAX(ABS(C30),1)),"PASS","FAIL")) -> FIXTURE NOT LOADED
A31: Storage support $/mo (Engine!B39) | B31: =Engine!$B$39 -> 4124.2122 | C31: 4167 | D31: =IF($B$21<>"YES","FIXTURE NOT LOADED",IF(ABS(B31-C31)<=MAX(1,0.0001*MAX(ABS(C31),1)),"PASS","FAIL")) -> FIXTURE NOT LOADED
A32: Power $/mo (Engine!B35) | B32: =Engine!$B$35 -> 7289.4476 | C32: 7320 | D32: =IF($B$21<>"YES","FIXTURE NOT LOADED",IF(ABS(B32-C32)<=MAX(1,0.0001*MAX(ABS(C32),1)),"PASS","FAIL")) -> FIXTURE NOT LOADED
A33: Other facility $/mo (Engine!B37) | B33: =Engine!$B$37 -> 3110.5453 | C33: 3111 | D33: =IF($B$21<>"YES","FIXTURE NOT LOADED",IF(ABS(B33-C33)<=MAX(1,0.0001*MAX(ABS(C33),1)),"PASS","FAIL")) -> FIXTURE NOT LOADED
A34: Admin $/mo (Engine!B38) | B34: =Engine!$B$38 -> 1575 | C34: 1575 | D34: =IF($B$21<>"YES","FIXTURE NOT LOADED",IF(ABS(B34-C34)<=MAX(1,0.0001*MAX(ABS(C34),1)),"PASS","FAIL")) -> FIXTURE NOT LOADED
A35: Selected opex $/mo (Engine!B42) | B35: =Engine!$B$42 -> 16099.205 | C35: 16173 | D35: =IF($B$21<>"YES","FIXTURE NOT LOADED",IF(ABS(B35-C35)<=MAX(1,0.0001*MAX(ABS(C35),1)),"PASS","FAIL")) -> FIXTURE NOT LOADED
A36: One-time costs (Engine!B54) | B36: =Engine!$B$54 -> 359648.79 | C36: 50000 | D36: =IF($B$21<>"YES","FIXTURE NOT LOADED",IF(ABS(B36-C36)<=MAX(1,0.0001*MAX(ABS(C36),1)),"PASS","FAIL")) -> FIXTURE NOT LOADED
A37: Residual credit (Engine!B55) | B37: =Engine!$B$55 -> 186767.81 | C37: 0 | D37: =IF($B$21<>"YES","FIXTURE NOT LOADED",IF(ABS(B37-C37)<=MAX(1,0.0001*MAX(ABS(C37),1)),"PASS","FAIL")) -> FIXTURE NOT LOADED
A38: Cloud storage + egress $/mo (Engine!B25) | B38: =Engine!$B$25 -> 51965.333 | C38: 52500 | D38: =IF($B$21<>"YES","FIXTURE NOT LOADED",IF(ABS(B38-C38)<=MAX(1,0.0001*MAX(ABS(C38),1)),"PASS","FAIL")) -> FIXTURE NOT LOADED
A39: Cloud admin $/mo (Engine!B26) | B39: =Engine!$B$26 -> 574.16667 | C39: 574 | D39: =IF($B$21<>"YES","FIXTURE NOT LOADED",IF(ABS(B39-C39)<=MAX(1,0.0001*MAX(ABS(C39),1)),"PASS","FAIL")) -> FIXTURE NOT LOADED
A40: Cloud monthly total (compute+storage+admin) | B40: =Engine!$B$5+Engine!$B$25+Engine!$B$26 -> 105079 | C40: 105079 | D40: =IF($B$21<>"YES","FIXTURE NOT LOADED",IF(ABS(B40-C40)<=MAX(1,0.0001*MAX(ABS(C40),1)),"PASS","FAIL")) -> FIXTURE NOT LOADED
A41: Equinix opex option $/mo (Engine!B41) | B41: =Engine!$B$41 -> 15511.212 | C41: 15554 | D41: =IF($B$21<>"YES","FIXTURE NOT LOADED",IF(ABS(B41-C41)<=MAX(1,0.0001*MAX(ABS(C41),1)),"PASS","FAIL")) -> FIXTURE NOT LOADED
A42: Lease view (blank factor → text) (Engine!B51) | B42: =Engine!$B$51 -> not entered | C42: not entered | D42: =IF($B$21<>"YES","FIXTURE NOT LOADED",IF(B42=C42,"PASS","FAIL")) -> FIXTURE NOT LOADED
...

Sheet Crossover
A1: Month | B1: Cloud cum ($) | C1: On-prem cum ($) | D1: Crossed | F1: v2.3: cumulative monthly cash flows from the STATED bill (single source of truth with Results): compute portion grows at demand rate, non-compute at RateCard ops growth; reconstructed components validate the bill (reconciliation) but do not replace it. On-prem = capex + one-time at month 1 + opex growing at RateCard ops growth. Residual excluded until exit.
A2: 1 | B2: =(Inputs!$B$4*Inputs!$B$13*(1+Inputs!$B$14)^INT((1-1)/12)+Inputs!$B$4*(1-Inputs!$B$13)*(1+RateCard!$B$37)^INT((1-1)/12)) -> 105079 | C2: =Engine!$B$33+Engine!$B$54+(Engine!$B$42*(1+RateCard!$B$37)^INT((1-1)/12)) -> 2403666.7 | D2: =IF(B2>=C2,1,0) -> 0
A3: 2 | B3: =B2+(Inputs!$B$4*Inputs!$B$13*(1+Inputs!$B$14)^INT((2-1)/12)+Inputs!$B$4*(1-Inputs!$B$13)*(1+RateCard!$B$37)^INT((2-1)/12)) -> 210158 | C3: =C2+(Engine!$B$42*(1+RateCard!$B$37)^INT((2-1)/12)) -> 2419765.9 | D3: =IF(B3>=C3,1,0) -> 0
A4: 3 | B4: =B3+(Inputs!$B$4*Inputs!$B$13*(1+Inputs!$B$14)^INT((3-1)/12)+Inputs!$B$4*(1-Inputs!$B$13)*(1+RateCard!$B$37)^INT((3-1)/12)) -> 315237 | C4: =C3+(Engine!$B$42*(1+RateCard!$B$37)^INT((3-1)/12)) -> 2435865.1 | D4: =IF(B4>=C4,1,0) -> 0
A5: 4 | B5: =B4+(Inputs!$B$4*Inputs!$B$13*(1+Inputs!$B$14)^INT((4-1)/12)+Inputs!$B$4*(1-Inputs!$B$13)*(1+RateCard!$B$37)^INT((4-1)/12)) -> 420316 | C5: =C4+(Engine!$B$42*(1+RateCard!$B$37)^INT((4-1)/12)) -> 2451964.3 | D5: =IF(B5>=C5,1,0) -> 0
A6: 5 | B6: =B5+(Inputs!$B$4*Inputs!$B$13*(1+Inputs!$B$14)^INT((5-1)/12)+Inputs!$B$4*(1-Inputs!$B$13)*(1+RateCard!$B$37)^INT((5-1)/12)) -> 525395 | C6: =C5+(Engine!$B$42*(1+RateCard!$B$37)^INT((5-1)/12)) -> 2468063.5 | D6: =IF(B6>=C6,1,0) -> 0
A7: 6 | B7: =B6+(Inputs!$B$4*Inputs!$B$13*(1+Inputs!$B$14)^INT((6-1)/12)+Inputs!$B$4*(1-Inputs!$B$13)*(1+RateCard!$B$37)^INT((6-1)/12)) -> 630474 | C7: =C6+(Engine!$B$42*(1+RateCard!$B$37)^INT((6-1)/12)) -> 2484162.7 | D7: =IF(B7>=C7,1,0) -> 0
A8: 7 | B8: =B7+(Inputs!$B$4*Inputs!$B$13*(1+Inputs!$B$14)^INT((7-1)/12)+Inputs!$B$4*(1-Inputs!$B$13)*(1+RateCard!$B$37)^INT((7-1)/12)) -> 735553 | C8: =C7+(Engine!$B$42*(1+RateCard!$B$37)^INT((7-1)/12)) -> 2500261.9 | D8: =IF(B8>=C8,1,0) -> 0
A9: 8 | B9: =B8+(Inputs!$B$4*Inputs!$B$13*(1+Inputs!$B$14)^INT((8-1)/12)+Inputs!$B$4*(1-Inputs!$B$13)*(1+RateCard!$B$37)^INT((8-1)/12)) -> 840632 | C9: =C8+(Engine!$B$42*(1+RateCard!$B$37)^INT((8-1)/12)) -> 2516361.1 | D9: =IF(B9>=C9,1,0) -> 0
A10: 9 | B10: =B9+(Inputs!$B$4*Inputs!$B$13*(1+Inputs!$B$14)^INT((9-1)/12)+Inputs!$B$4*(1-Inputs!$B$13)*(1+RateCard!$B$37)^INT((9-1)/12)) -> 945711 | C10: =C9+(Engine!$B$42*(1+RateCard!$B$37)^INT((9-1)/12)) -> 2532460.4 | D10: =IF(B10>=C10,1,0) -> 0
A11: 10 | B11: =B10+(Inputs!$B$4*Inputs!$B$13*(1+Inputs!$B$14)^INT((10-1)/12)+Inputs!$B$4*(1-Inputs!$B$13)*(1+RateCard!$B$37)^INT((10-1)/12)) -> 1050790 | C11: =C10+(Engine!$B$42*(1+RateCard!$B$37)^INT((10-1)/12)) -> 2548559.6 | D11: =IF(B11>=C11,1,0) -> 0
A12: 11 | B12: =B11+(Inputs!$B$4*Inputs!$B$13*(1+Inputs!$B$14)^INT((11-1)/12)+Inputs!$B$4*(1-Inputs!$B$13)*(1+RateCard!$B$37)^INT((11-1)/12)) -> 1155869 | C12: =C11+(Engine!$B$42*(1+RateCard!$B$37)^INT((11-1)/12)) -> 2564658.8 | D12: =IF(B12>=C12,1,0) -> 0
A13: 12 | B13: =B12+(Inputs!$B$4*Inputs!$B$13*(1+Inputs!$B$14)^INT((12-1)/12)+Inputs!$B$4*(1-Inputs!$B$13)*(1+RateCard!$B$37)^INT((12-1)/12)) -> 1260948 | C13: =C12+(Engine!$B$42*(1+RateCard!$B$37)^INT((12-1)/12)) -> 2580758 | D13: =IF(B13>=C13,1,0) -> 0
A14: 13 | B14: =B13+(Inputs!$B$4*Inputs!$B$13*(1+Inputs!$B$14)^INT((13-1)/12)+Inputs!$B$4*(1-Inputs!$B$13)*(1+RateCard!$B$37)^INT((13-1)/12)) -> 1381263.5 | C14: =C13+(Engine!$B$42*(1+RateCard!$B$37)^INT((13-1)/12)) -> 2597501.1 | D14: =IF(B14>=C14,1,0) -> 0
A15: 14 | B15: =B14+(Inputs!$B$4*Inputs!$B$13*(1+Inputs!$B$14)^INT((14-1)/12)+Inputs!$B$4*(1-Inputs!$B$13)*(1+RateCard!$B$37)^INT((14-1)/12)) -> 1501578.9 | C15: =C14+(Engine!$B$42*(1+RateCard!$B$37)^INT((14-1)/12)) -> 2614244.3 | D15: =IF(B15>=C15,1,0) -> 0
A16: 15 | B16: =B15+(Inputs!$B$4*Inputs!$B$13*(1+Inputs!$B$14)^INT((15-1)/12)+Inputs!$B$4*(1-Inputs!$B$13)*(1+RateCard!$B$37)^INT((15-1)/12)) -> 1621894.4 | C16: =C15+(Engine!$B$42*(1+RateCard!$B$37)^INT((15-1)/12)) -> 2630987.5 | D16: =IF(B16>=C16,1,0) -> 0
A17: 16 | B17: =B16+(Inputs!$B$4*Inputs!$B$13*(1+Inputs!$B$14)^INT((16-1)/12)+Inputs!$B$4*(1-Inputs!$B$13)*(1+RateCard!$B$37)^INT((16-1)/12)) -> 1742209.8 | C17: =C16+(Engine!$B$42*(1+RateCard!$B$37)^INT((16-1)/12)) -> 2647730.7 | D17: =IF(B17>=C17,1,0) -> 0
A18: 17 | B18: =B17+(Inputs!$B$4*Inputs!$B$13*(1+Inputs!$B$14)^INT((17-1)/12)+Inputs!$B$4*(1-Inputs!$B$13)*(1+RateCard!$B$37)^INT((17-1)/12)) -> 1862525.3 | C18: =C17+(Engine!$B$42*(1+RateCard!$B$37)^INT((17-1)/12)) -> 2664473.8 | D18: =IF(B18>=C18,1,0) -> 0
A19: 18 | B19: =B18+(Inputs!$B$4*Inputs!$B$13*(1+Inputs!$B$14)^INT((18-1)/12)+Inputs!$B$4*(1-Inputs!$B$13)*(1+RateCard!$B$37)^INT((18-1)/12)) -> 1982840.7 | C19: =C18+(Engine!$B$42*(1+RateCard!$B$37)^INT((18-1)/12)) -> 2681217 | D19: =IF(B19>=C19,1,0) -> 0
A20: 19 | B20: =B19+(Inputs!$B$4*Inputs!$B$13*(1+Inputs!$B$14)^INT((19-1)/12)+Inputs!$B$4*(1-Inputs!$B$13)*(1+RateCard!$B$37)^INT((19-1)/12)) -> 2103156.2 | C20: =C19+(Engine!$B$42*(1+RateCard!$B$37)^INT((19-1)/12)) -> 2697960.2 | D20: =IF(B20>=C20,1,0) -> 0
A21: 20 | B21: =B20+(Inputs!$B$4*Inputs!$B$13*(1+Inputs!$B$14)^INT((20-1)/12)+Inputs!$B$4*(1-Inputs!$B$13)*(1+RateCard!$B$37)^INT((20-1)/12)) -> 2223471.6 | C21: =C20+(Engine!$B$42*(1+RateCard!$B$37)^INT((20-1)/12)) -> 2714703.4 | D21: =IF(B21>=C21,1,0) -> 0
A22: 21 | B22: =B21+(Inputs!$B$4*Inputs!$B$13*(1+Inputs!$B$14)^INT((21-1)/12)+Inputs!$B$4*(1-Inputs!$B$13)*(1+RateCard!$B$37)^INT((21-1)/12)) -> 2343787.1 | C22: =C21+(Engine!$B$42*(1+RateCard!$B$37)^INT((21-1)/12)) -> 2731446.5 | D22: =IF(B22>=C22,1,0) -> 0
A23: 22 | B23: =B22+(Inputs!$B$4*Inputs!$B$13*(1+Inputs!$B$14)^INT((22-1)/12)+Inputs!$B$4*(1-Inputs!$B$13)*(1+RateCard!$B$37)^INT((22-1)/12)) -> 2464102.5 | C23: =C22+(Engine!$B$42*(1+RateCard!$B$37)^INT((22-1)/12)) -> 2748189.7 | D23: =IF(B23>=C23,1,0) -> 0
A24: 23 | B24: =B23+(Inputs!$B$4*Inputs!$B$13*(1+Inputs!$B$14)^INT((23-1)/12)+Inputs!$B$4*(1-Inputs!$B$13)*(1+RateCard!$B$37)^INT((23-1)/12)) -> 2584418 | C24: =C23+(Engine!$B$42*(1+RateCard!$B$37)^INT((23-1)/12)) -> 2764932.9 | D24: =IF(B24>=C24,1,0) -> 0
A25: 24 | B25: =B24+(Inputs!$B$4*Inputs!$B$13*(1+Inputs!$B$14)^INT((24-1)/12)+Inputs!$B$4*(1-Inputs!$B$13)*(1+RateCard!$B$37)^INT((24-1)/12)) -> 2704733.5 | C25: =C24+(Engine!$B$42*(1+RateCard!$B$37)^INT((24-1)/12)) -> 2781676 | D25: =IF(B25>=C25,1,0) -> 0
A26: 25 | B26: =B25+(Inputs!$B$4*Inputs!$B$13*(1+Inputs!$B$14)^INT((25-1)/12)+Inputs!$B$4*(1-Inputs!$B$13)*(1+RateCard!$B$37)^INT((25-1)/12)) -> 2843653.2 | C26: =C25+(Engine!$B$42*(1+RateCard!$B$37)^INT((25-1)/12)) -> 2799088.9 | D26: =IF(B26>=C26,1,0) -> 1
A27: 26 | B27: =B26+(Inputs!$B$4*Inputs!$B$13*(1+Inputs!$B$14)^INT((26-1)/12)+Inputs!$B$4*(1-Inputs!$B$13)*(1+RateCard!$B$37)^INT((26-1)/12)) -> 2982572.8 | C27: =C26+(Engine!$B$42*(1+RateCard!$B$37)^INT((26-1)/12)) -> 2816501.9 | D27: =IF(B27>=C27,1,0) -> 1
A28: 27 | B28: =B27+(Inputs!$B$4*Inputs!$B$13*(1+Inputs!$B$14)^INT((27-1)/12)+Inputs!$B$4*(1-Inputs!$B$13)*(1+RateCard!$B$37)^INT((27-1)/12)) -> 3121492.5 | C28: =C27+(Engine!$B$42*(1+RateCard!$B$37)^INT((27-1)/12)) -> 2833914.8 | D28: =IF(B28>=C28,1,0) -> 1
A29: 28 | B29: =B28+(Inputs!$B$4*Inputs!$B$13*(1+Inputs!$B$14)^INT((28-1)/12)+Inputs!$B$4*(1-Inputs!$B$13)*(1+RateCard!$B$37)^INT((28-1)/12)) -> 3260412.2 | C29: =C28+(Engine!$B$42*(1+RateCard!$B$37)^INT((28-1)/12)) -> 2851327.7 | D29: =IF(B29>=C29,1,0) -> 1
A30: 29 | B30: =B29+(Inputs!$B$4*Inputs!$B$13*(1+Inputs!$B$14)^INT((29-1)/12)+Inputs!$B$4*(1-Inputs!$B$13)*(1+RateCard!$B$37)^INT((29-1)/12)) -> 3399331.9 | C30: =C29+(Engine!$B$42*(1+RateCard!$B$37)^INT((29-1)/12)) -> 2868740.6 | D30: =IF(B30>=C30,1,0) -> 1
A31: 30 | B31: =B30+(Inputs!$B$4*Inputs!$B$13*(1+Inputs!$B$14)^INT((30-1)/12)+Inputs!$B$4*(1-Inputs!$B$13)*(1+RateCard!$B$37)^INT((30-1)/12)) -> 3538251.6 | C31: =C30+(Engine!$B$42*(1+RateCard!$B$37)^INT((30-1)/12)) -> 2886153.5 | D31: =IF(B31>=C31,1,0) -> 1
A32: 31 | B32: =B31+(Inputs!$B$4*Inputs!$B$13*(1+Inputs!$B$14)^INT((31-1)/12)+Inputs!$B$4*(1-Inputs!$B$13)*(1+RateCard!$B$37)^INT((31-1)/12)) -> 3677171.3 | C32: =C31+(Engine!$B$42*(1+RateCard!$B$37)^INT((31-1)/12)) -> 2903566.4 | D32: =IF(B32>=C32,1,0) -> 1
A33: 32 | B33: =B32+(Inputs!$B$4*Inputs!$B$13*(1+Inputs!$B$14)^INT((32-1)/12)+Inputs!$B$4*(1-Inputs!$B$13)*(1+RateCard!$B$37)^INT((32-1)/12)) -> 3816091 | C33: =C32+(Engine!$B$42*(1+RateCard!$B$37)^INT((32-1)/12)) -> 2920979.3 | D33: =IF(B33>=C33,1,0) -> 1
A34: 33 | B34: =B33+(Inputs!$B$4*Inputs!$B$13*(1+Inputs!$B$14)^INT((33-1)/12)+Inputs!$B$4*(1-Inputs!$B$13)*(1+RateCard!$B$37)^INT((33-1)/12)) -> 3955010.7 | C34: =C33+(Engine!$B$42*(1+RateCard!$B$37)^INT((33-1)/12)) -> 2938392.2 | D34: =IF(B34>=C34,1,0) -> 1
A35: 34 | B35: =B34+(Inputs!$B$4*Inputs!$B$13*(1+Inputs!$B$14)^INT((34-1)/12)+Inputs!$B$4*(1-Inputs!$B$13)*(1+RateCard!$B$37)^INT((34-1)/12)) -> 4093930.4 | C35: =C34+(Engine!$B$42*(1+RateCard!$B$37)^INT((34-1)/12)) -> 2955805.1 | D35: =IF(B35>=C35,1,0) -> 1
A36: 35 | B36: =B35+(Inputs!$B$4*Inputs!$B$13*(1+Inputs!$B$14)^INT((35-1)/12)+Inputs!$B$4*(1-Inputs!$B$13)*(1+RateCard!$B$37)^INT((35-1)/12)) -> 4232850.1 | C36: =C35+(Engine!$B$42*(1+RateCard!$B$37)^INT((35-1)/12)) -> 2973218 | D36: =IF(B36>=C36,1,0) -> 1
A37: 36 | B37: =B36+(Inputs!$B$4*Inputs!$B$13*(1+Inputs!$B$14)^INT((36-1)/12)+Inputs!$B$4*(1-Inputs!$B$13)*(1+RateCard!$B$37)^INT((36-1)/12)) -> 4371769.8 | C37: =C36+(Engine!$B$42*(1+RateCard!$B$37)^INT((36-1)/12)) -> 2990630.9 | D37: =IF(B37>=C37,1,0) -> 1
A38: 37 | B38: =B37+(Inputs!$B$4*Inputs!$B$13*(1+Inputs!$B$14)^INT((37-1)/12)+Inputs!$B$4*(1-Inputs!$B$13)*(1+RateCard!$B$37)^INT((37-1)/12)) -> 4533485.8 | C38: =C37+(Engine!$B$42*(1+RateCard!$B$37)^INT((37-1)/12)) -> 3008740.3 | D38: =IF(B38>=C38,1,0) -> 1
A39: 38 | B39: =B38+(Inputs!$B$4*Inputs!$B$13*(1+Inputs!$B$14)^INT((38-1)/12)+Inputs!$B$4*(1-Inputs!$B$13)*(1+RateCard!$B$37)^INT((38-1)/12)) -> 4695201.8 | C39: =C38+(Engine!$B$42*(1+RateCard!$B$37)^INT((38-1)/12)) -> 3026849.7 | D39: =IF(B39>=C39,1,0) -> 1
A40: 39 | B40: =B39+(Inputs!$B$4*Inputs!$B$13*(1+Inputs!$B$14)^INT((39-1)/12)+Inputs!$B$4*(1-Inputs!$B$13)*(1+RateCard!$B$37)^INT((39-1)/12)) -> 4856917.8 | C40: =C39+(Engine!$B$42*(1+RateCard!$B$37)^INT((39-1)/12)) -> 3044959.1 | D40: =IF(B40>=C40,1,0) -> 1
...
